Workbook

Sheet Irrigation
M1: Technical Form No.GSDA/IRR/DW/2025 | R1: Select Sr.No. -> | S1: 1
A2: Irrigation Dug well Inventory form
A3: 1 | B3: Name of Geologist | H3: 2 | I3: Designation
A4: 3 | B4: Date of Inventory (DD/MM/YY) | F4: 4 | G4: Time (24 Hrs format) | J4: 5 | K4: Project/Assignment for which Inventory is being done
A5: A | B5: Well Location details
A6: 1 | B6: Well No. (Sequence No. in the 10K sheet) | F6: 2 | G6: Type of well (DW/DCB) | K6: 3 | L6: Altitude (m.MSL) | N6: GL | P6: MP | Q6: =O6+P19
A7: 4 | B7: Owner's Name and Address | G7: PWS WELL GP Karjal
A8: 5 | B8: Village Name | F8: 6 | G8: G.P. Name | K8: 7 | L8: Village Census No.
A9: 8 | B9: Taluka Name | F9: 9 | G9: District Name | K9: 10 | L9: Mini Watershed No.
A10: 11 | B10: SOI Toposheet No. | F10: 12 | G10: 10 K Sheet No. | K10: 13 | L10: Quadrant No.of 10K Sheet (EX-A1)
A11: 14 | B11: Latitude (DD) | F11: 15 | G11: Longitude (DD)
B12: Latitude (DMS) | C12: =INT(C11) | D12: =INT((C11-INT(C11))*60) | E12: =((C11-INT(C11))*60-INT((C11-INT(C11))*60))*60 | G12: Longitude (DMS) | H12: =INT(H11) | I12: =INT((H11-INT(H11))*60) | J12: =((H11-INT(H11))*60-INT((H11-INT(H11))*60))*60 | K12: 16 | L12: Gat/Survey No.
A13: 17 | B13: Well ID (Census no+Lat+long+type of well | G13: =O8&C11&H11&H6
A14: 18 | B14: Whether the well is located in command area of any surface water reservoir (projects) (if yes mention the following details)
B15: Name of the Reservour (project) | J15: Type (major/medium/mionr/PT)
B16: Distance and Direction of reservoir from the well | J16: Name of the nearest Canal of the project
B17: Distance and Direction of the Canal from the well | J17: Nature of operartion of Canal (Seasonal/perennial)
A18: B | B18: Well Dimensions :
A19: 1 | B19: Measurement point (MP) (e.g. on GL/Parapet due N40 | K19: 2 | L19: Height of Parapet (m.bgl)
A20: 3 | B20: Inner Diameter of Dug Well (DW) in m. | H20: Top | K20: Bottom | O20: Effective
A21: 4 | B21: Lining/Curbing Material (Brick/RCC/Stone pitching | K21: 5 | L21: Depth of Lining (m.bgl)
A22: 6 | B22: Condition of Well and Lining | K22: 7 | L22: Year of Construction
A23: 8 | B23: Depth of Dug Well (DW) m.bgl | H23: 9 | I23: Depth of Inwell Borehole from bottom of well (m) | P23: -
A24: 10 | B24: Total Depth of Dug Cum Borewell (=Depth of DW+Depth of Inwell Borehole) if Applicable (in m.bgl) | P24: -
A25: C | B25: Groundwater level and Pumping details
A26: 1 | B26: Pump type (Monoblock/Open well submersible) | J26: 2 | K26: Mode of Power (Electric/Solar)
A27: 3 | B27: HP of pump | F27: 4 | G27: Pump Setting | H27: Winter | J27: =F23 | L27: m.bgl | M27: Summer | O27: =F23 | Q27: m.bgl
A28: 5 | B28: Depth of pump inlet | H28: Winter | J28: =F23 | L28: m.bgl | M28: Summer | O28: =F23 | Q28: m.bgl
A29: 6 | B29: Diameter of Pipe(mm) | D29: Suction pipe | G29: 50.5 | H29: Delivery pipe | K29: 63.5 | M29: Delivery pipe material | P29: HDPE
A30: 7 | B30: Pump discharge (m3/hour) | H30: Method Used For Discharge measurement | O30: Adhoc
A31: 8 | B31: Depth to Pumped groundwater level (DWL) | H31: m.bgl | I31: mention depth to groundwater level at the time of measurment)
A32: 9 | B32: Depth to Static groundwater level (SWL) (Reported R for previous season) | G32: Winter | I32: m.bgl | J32: Summer | M32: m.bgl | N32: Annual Water Level fluctuation (m) | Q32: =L32-H32
A33: 10 | B33: Depth to Pumped groundwater level (PWL) | G33: Winter | I33: m.bgl | J33: summer | M33: m.bgl | N33: (DWL just before pumping stopped) mention R if reported (e.g.10 (R))
A34: 11 | B34: Drawdown (D/D) (PWL - SWL) | G34: Winter | J34: m. | L34: Summer | P34: m.
A35: 12 | B35: Duration of Pumping | G35: Winter | J35: Hrs | L35: Summer | P35: Hrs
A36: 13 | B36: Quantity of water pumped | G36: Winter | J36: M3 | L36: Summer | P36: m3
A37: 14 | B37: Volume of water Pumped from Storage | G37: Winter | J37: M3 | L37: Summer | P37: m3
A38: 15 | B38: Avg. Rate of Inflow during pumping | G38: Winter | J38: M3/Hr | L38: Summer | P38: M3/Hr
A39: 16 | B39: Time required for complete recuperation | G39: Winter | J39: Hrs | L39: Summer | P39: Hrs
A40: D | B40: Well Performance
...

Sheet PWS
L1: Technical Form No.GSDA/PWS/DW/2025 | R1: Select Sr.No. -> | S1: 1
A2: PWS Dug well Inventory form
A3: 1 | B3: Name of Geologist | H3: 2 | I3: Designation
A4: 3 | B4: Date of Inventory (DD/MM/YY) | F4: 4 | G4: Time (24 Hrs format) | J4: 5 | K4: Project/Assignment for which Inventory is being done
A5: A | B5: Well Location details
A6: 1 | B6: Well No. (Sequence No. in the 10K sheet) | F6: 2 | G6: Type of well (DW/DCB) | K6: 3 | L6: Altitude (m.MSL) | N6: GL | P6: MP | Q6: =O6+P36
A7: 4 | B7: Name of Village in whose area the well is Located | K7: 5 | L7: Village Census No.
A8: 6 | B8: Taluka Name | F8: 7 | G8: District Name | K8: 8 | L8: Mini Watershed No.
A9: 9 | B9: SOI Toposheet No. | F9: 10 | G9: 10 K Sheet No. | K9: 11 | L9: Quadrant No.of 10K Sheet (EX-A1)
A10: 12 | B10: Latitude(DMS) | F10: 13 | G10: Longitude(DMS) | K10: 14 | L10: Gat/Survey No.
B11: Latitude (DMS) | C11: 18.161307 | D11: =INT((C10-INT(C10))*60) | E11: =((C10-INT(C10))*60-INT((C10-INT(C10))*60))*60 | G11: Longitude (DMS) | H11: 76.389438 | I11: =INT((H10-INT(H10))*60) | J11: =((H10-INT(H10))*60-INT((H10-INT(H10))*60))*60
A12: 15 | B12: Well ID (Census no+Lat+long+type of well | G12: =O7&C10&H10&H6
A13: 16 | B13: Whether the well is located in command area of any surface water reservoir (projects) (if yes mention the following details)
B14: Name of the Reservour (project) | J14: Type (major/medium/mionr/PT)
B15: Distance and Direction of reservoir from the well | J15: Name of the nearest Canal of the project
B16: Distance and Direction of the Canal from the well | J16: Nature of operartion of Canal (Seasonal/perennial)
A17: B1 | B17: Village Water Supply Details (Applicable for Domestic or PWS Well)
A18: 1 | B18: Name of Village to which water is supplied (Owner of PWS Well)
A19: 2 | B19: G.P.Name | G19: Taluka | K19: 4 | L19: District Name
A20: 5 | B20: Distance and Direction of Village from Water Supply Well
A21: 6 | B21: Storage Capacity of ESR/GSR (Cum) | K21: =(((G22*1.28)*55)/1000)/2
A22: 7 | B22: Population covered | H22: Water requirement in m3per day (@55 lpcd) | O22: =((G22*1.28)*55)/1000 | R22: =G22*1.28
A23: 8 | B23: Cattles covered | G23: =G22*0.2 | H23: Water requirement in m3per day (@30 lpcd) | O23: =(G23*30)/1000
A24: 9 | B24: Status of Use(Perennial/Seasonal(mention month upto which it sustains) | K24: Perennial
A25: 10 | B25: Dependency of Source (in %) If not 100% mention other means of supply | K25: 1
A26: 11 | B26: Quality of water (Potable/Non potable)(R) | K26: Potable
A27: B2 | B27: Industry Water Supply Details (Applicable for Industrial Well)
A28: 1 | B28: Name of Industry to which water is supplied (Owner of Well) | K28: -
A29: 2 | B29: Distance and Direction of Industry from Water Supply Well | K29: -
A30: 3 | B30: Storage Capacity of ESR/GSR (Cum) | K30: -
A31: 4 | B31: Use of water for (Drinking/Industrial/Other) | K31: -
A32: 5 | B32: Water utilisation/Requirement in m3per day | K32: -
A33: 6 | B33: Status of Use(Perennial/Seasonal(mention month upto which it sustains) | K33: -
A34: 7 | B34: Quality of water (Potable/Non potable)(R) | K34: -
A35: C | B35: Well Dimensions :
A36: 1 | B36: Measurement point (MP) (e.g. on GL/Parapet due N40 | K36: 2 | L36: Height of Parapet (m.bgl)
A37: 3 | B37: Inner Diameter of Dug Well (DW) in m. | H37: Top | K37: Bottom | O37: Effective
A38: 4 | B38: Lining/Curbing Material (Brick/RCC/Stone pitching | K38: 5 | L38: Depth of Lining (m.bgl)
A39: 6 | B39: Condition of Well and Lining | K39: 7 | L39: Year of Construction
A40: 8 | B40: Depth of Dug Well (DW) m.bgl | H40: 18 | I40: Depth of Inwell Borehole from bottom of well (m) | P40: -
...

Sheet calc
A1: Sr.No. | B1: Date | C1: Time | D1: Geologist Name | E1: Mapsheetno | F1: well no | G1: Type of well | H1: Well Owner | I1: District Name | J1: Taluka Name | K1: Gp Name | L1: Village Name | M1: Cencess no | N1: Toposheet no | O1: mini watershed | P1: Population | Q1: LatLong | R1: Altitude | S1: Gat no | T1: Qurdant | U1: Measuring Point | V1: Parapet (m) | W1: Diameter (m) | X1: effec. Dia | Y1: Depth | Z1: Curbing (m) | AA1: Type of curbing | AB1: Year of Construction | AC1: DwL | AD1: Winter (SWL) | AE1: Summer (SWL) | AF1: Type of Pump | AG1: Mode of Power | AH1: HP | AI1: Winter pumping hrs | AJ1: Summer pumping hrs | AK1: winter T req recuperation | AL1: Summer T req recuperation | AM1: Project Irri(PT/MInor) | AN1: Distance | AO1: Canal | AP1: Distance c | AQ1: Cultivable land (Ha) | AR1: Kharif Crop1 | AS1: Kharif Crop2 | AT1: Kharif Crop3 | AU1: Kharif Crop land Flood (Ha)1 | AV1: Kharif Crop land Flood (Ha)2 | AW1: Kharif Crop land Flood (Ha)3 | AX1: Kharif Crop land Sprinkler (Ha)1 | AY1: Kharif Crop land Sprinkler (Ha)2 | AZ1: Kharif Crop land Sprinkler (Ha)3 | BA1: Kharif Crop land Drip (Ha)1 | BB1: Kharif Crop land Drip (Ha)2 | BC1: Kharif Crop land Drip (Ha)3 | BD1: Rabbi Crop1 | BE1: RabbiCrop2 | BF1: Rabbi Crop3 | BG1: Rabbi Crop land Flood (Ha)1 | BH1: Rabbi Crop land Flood (Ha)2 | BI1: Rabbi Crop land Flood (Ha)3 | BJ1: Rabbi Crop land Sprinkler (Ha)1 | BK1: Rabbi Crop land Sprinkler (Ha)2 | BL1: Rabbi Crop land Sprinkler (Ha)3 | BM1: Rabbi Crop land Drip (Ha)1 | BN1: Rabbi Crop land Drip (Ha)2 | BO1: Rabbi Crop land Drip (Ha)3 | BP1: Perennial Crop 1 | BQ1: Perennial Crop 2 | BR1: Perennial Crop 1 Flood land (Ha) | BS1: Perennial Crop 2 Flood land (Ha) | BT1: Perennial Crop 1 Sprinkler land (Ha) | BU1: Perennial Crop 2 Sprinkler land (Ha) | BV1: Perennial Crop 1 Drip land (Ha) | BW1: Perennial Crop 2 Drip land (Ha) | BX1: Summer Crops 1 | BY1: Summer Crops 2 | BZ1: Summer Crop Flood 1 land (Ha) | CA1: Summer Crop Flood 2 land (Ha) | CB1: Summer Crop Sprinkler 1 land (Ha) | CC1: Summer Crop Sprinkler 2 land (Ha) | CD1: Summer Crop Drip 1 land (Ha) | CE1: Summer Crop Drip 2 land (Ha) | CF1: Photo | CG1: Litho 1 | CH1: Depth Litho 1 | CI1: Litho 2 | CJ1: Depth Litho 2 | CK1: Litho 3 | CL1: Depth Litho 3 | CM1: Litho4 | CN1: Depth Litho4 | CO1: Litho 5 | CP1: Depth Litho 5 | CQ1: nearest well | CR1: Remarks | CS1: Perennial 1 Kharif Waterings | CT1: Perennial 1 Kharif Depth (m) | CU1: Perennial 2 Kharif Waterings | CV1: Perennial 2 Kharif Depth (m) | CW1: Kharif 1 Waterings | CX1: Kharif 1 Depth (m) | CY1: Kharif 2 Waterings | CZ1: Kharif 2 Depth (m) | DA1: Kharif 3 Waterings | DB1: Kharif 3 Depth (m) | DC1: Perennial 1 Rabi Waterings | DD1: Perennial 1 Rabi Depth (m) | DE1: Perennial 2 Rabi Waterings | DF1: Perennial 2 Rabi Depth (m) | DG1: Rabi 1 Waterings | DH1: Rabi 1 Depth (m) | DI1: Rabi 2 Waterings | DJ1: Rabi 2 Depth (m) | DK1: Rabi 3 Waterings | DL1: Rabi 3 Depth (m) | DM1: Perennial 1 Summer Waterings | DN1: Perennial 1 Summer Depth (m) | DO1: Perennial 2 Summer Waterings | DP1: Perennial 2 Summer Depth (m) | DQ1: Summer 1 Waterings | DR1: Summer 1 Depth (m) | DS1: Summer 2 Waterings | DT1: Summer 2 Depth (m)

Sheet All Collected Data
A1: Sr. No. | B1: Smart Hydro-Geo ID | C1: Survey Category | D1: Date | E1: Time | F1: Geologist Name | G1: Designation | H1: Project Assignment | I1: Well Seq No | J1: Well Type | K1: Well Owner | L1: District Name | M1: Taluka Name | N1: Gp Name | O1: Village Name | P1: Census No | Q1: Toposheet no | R1: mini watershed | S1: Mapsheetno | T1: Qurdant | U1: Gat no | V1: Lat (Degree Decimal) | W1: Long (Degree Decimal) | X1: Altitude GL (m) | Y1: Measuring Point | Z1: Parapet (m) | AA1: Diameter Top (m) | AB1: Diameter Bottom (m) | AC1: effec. Dia (m) | AD1: Type of curbing | AE1: Curbing (m) | AF1: Well Condition | AG1: Year of Construction | AH1: Depth (m) | AI1: Depth of Inwell BW (m) | AJ1: Type of Pump | AK1: Mode of Power | AL1: HP | AM1: Winter Pump Setting (m) | AN1: Summer Pump Setting (m) | AO1: Winter Pump Inlet (m) | AP1: Summer Pump Inlet (m) | AQ1: Discharge (m3/hr) | AR1: Discharge Method | AS1: Kharif Pumping Daily Hrs | AT1: Winter pumping hrs | AU1: Summer pumping hrs | AV1: DwL (m) | AW1: Winter (SWL) (m) | AX1: Winter (PWL) (m) | AY1: Winter Drawdown (m) | AZ1: Winter Qty Pumped (m3) | BA1: Winter Vol Storage (m3) | BB1: Winter Inflow Rate (m3/hr) | BC1: winter T req recuperation (hrs) | BD1: Summer (SWL) (m) | BE1: Summer (PWL) (m) | BF1: Summer Drawdown (m) | BG1: Summer Qty Pumped (m3) | BH1: Summer Vol Storage (m3) | BI1: Summer Inflow Rate (m3/hr) | BJ1: Summer T req recuperation (hrs) | BK1: Annual Fluctuation (m) | BL1: Project Irri(PT/Minor) | BM1: Reservoir Type | BN1: Reservoir Distance & Direction | BO1: Canal | BP1: Canal Distance & Direction | BQ1: Canal Operation Status | BR1: PWS Population | BS1: PWS Cattle Count | BT1: PWS Human Water Req (m3/day) | BU1: PWS Cattle Water Req (m3/day) | BV1: PWS Storage Capacity Req (m3) | BW1: Cultivable land (Ha) | BX1: Kharif Season Total Days (P59) | BY1: Rabi Season Total Days (P66) | BZ1: Summer Season Total Days (P72) | CA1: Grand Total Season Days (P73) | CB1: Kharif GW Draft (Ham) | CC1: Rabi GW Draft (Ham) | CD1: Summer GW Draft (Ham) | CE1: Total GW Draft (Ham) | CF1: Litho 1 | CG1: Depth Litho 1 (m) | CH1: Litho 2 | CI1: Depth Litho 2 (m) | CJ1: Litho 3 | CK1: Depth Litho 3 (m) | CL1: Litho 4 | CM1: Depth Litho 4 (m) | CN1: Litho 5 | CO1: Depth Litho 5 (m) | CP1: Inflow Zone Depth (m) | CQ1: nearest well | CR1: Photo | CS1: Remarks | CT1: Total Kharif Cropped Area (Ha) | CU1: Total Rabi Cropped Area (Ha) | CV1: Total Summer Cropped Area (Ha) | CW1: Total Cropped Area (Ha) | CX1: Perennial Crop 1 | CY1: Perennial 1 Flood (Ha) | CZ1: Perennial 1 Sprinkler (Ha) | DA1: Perennial 1 Drip (Ha) | DB1: Perennial Crop 2 | DC1: Perennial 2 Flood (Ha) | DD1: Perennial 2 Sprinkler (Ha) | DE1: Perennial 2 Drip (Ha) | DF1: Kharif Crop 1 | DG1: Kharif 1 Flood (Ha) | DH1: Kharif 1 Sprinkler (Ha) | DI1: Kharif 1 Drip (Ha) | DJ1: Kharif Crop 2 | DK1: Kharif 2 Flood (Ha) | DL1: Kharif 2 Sprinkler (Ha) | DM1: Kharif 2 Drip (Ha) | DN1: Kharif Crop 3 | DO1: Kharif 3 Flood (Ha) | DP1: Kharif 3 Sprinkler (Ha) | DQ1: Kharif 3 Drip (Ha) | DR1: Rabi Crop 1 | DS1: Rabi 1 Flood (Ha) | DT1: Rabi 1 Sprinkler (Ha) | DU1: Rabi 1 Drip (Ha) | DV1: Rabi Crop 2 | DW1: Rabi 2 Flood (Ha) | DX1: Rabi 2 Sprinkler (Ha) | DY1: Rabi 2 Drip (Ha) | DZ1: Rabi Crop 3 | EA1: Rabi 3 Flood (Ha) | EB1: Rabi 3 Sprinkler (Ha) | EC1: Rabi 3 Drip (Ha) | ED1: Summer Crop 1 | EE1: Summer 1 Flood (Ha) | EF1: Summer 1 Sprinkler (Ha) | EG1: Summer 1 Drip (Ha) | EH1: Summer Crop 2 | EI1: Summer 2 Flood (Ha) | EJ1: Summer 2 Sprinkler (Ha) | EK1: Summer 2 Drip (Ha)

Sheet MRSAC Format
A1: Sr. No. | B1: Taluka | C1: Village | D1: Owner Name | E1: Date of Survey | F1: Type of Well (DW/DCB/BW/TW) | G1: Gat No. | H1: 10K Sheet Quadrant | I1: Lat (Degree Decimal) | J1: Long (Degree Decimal) | K1: Depth bgl (M.) | L1: Dia (mm.) | M1: Curving (M.) | N1: Depth of Inwell BW (M.) | O1: Static Water Level (M.) Oct. | P1: May | Q1: At the time of visit | R1: Well Yield Ham. Khariff | S1: Rabbi | T1: Summer | U1: Total | V1: Well status Perennial/Seasonal | W1: Surveyed by | X1: Remark | Y1: 10K Sheet No.
